大家应该都遇到过在 JavaScript 解析或执行时，一旦发生错误，引擎就会抛出一个错误对象。接下来就来初步理解下 JavaScript 的错误处理机制。

### Error 对象

JavaScript 原生提供一个 Error 构造函数，所有抛出的错误都是这个构造函数的实例。

```javascript
var err = new Error('出错了')
err.message // "出错了"
```

调用 `Error` 构造函数，生成一个 `err` 实例

`Error` 构造函数接受一个参数，表示错误提示，可以从实例的 `message` 属性读到这个参数。

代码解析或运行时发生错误，JavaScript 引擎就会自动产生、并抛出一个 `Error` 对象的实例，然后整个程序就中断在发生错误的地方，不再往下执行。

---

### JavaScript 的原生错误类型

> Error 对象是最一般的错误类型，在它的基础上，JavaScript 还定义了其他 6 种错误，也就是说，存在 Error 的 6 个派生对象。

1. **SyntaxError**

    > `SyntaxError` 是解析代码时发生的「语法错误」。

    ```javascript
    // 变量名错误
    var 1a // SyntaxError: Invalid or unexpected token

    // 缺少括号
    console.log 'hello') // SyntaxError: Unexpected string
    ```

2. **ReferenceError**

    > `ReferenceError` 是「引用一个不存在的变量」时发生的错误。

    ```javascript
    unknownVariable
    // ReferenceError: unknownVariable is not defined
    ```

    另一种触发场景是：将一个值分配给「无法分配的对象」，比如对函数的运行结果或者 this 进行赋值。

    ```javascript
    console.log() = 1
    // ReferenceError: Invalid left-hand side in assignment

    this = 1
    // ReferenceError: Invalid left-hand side in assignment
    ```

3. **RangeError**

    > `RangeError` 是当一个值「超出有效范围」时发生的错误。
    
    可能的情况有：一是数组长度为**负数**，二是 Number 对象的方法参数超出范围，以及函数堆栈超过最大值。

    ```javascript
    new Array(-1)
    // RangeError: Invalid array length

    (1234).toExponential(233)
    // RangeError: toExponential() argument must be between 0 and 100
    ```

4. **TypeError**

    > `TypeError` 是变量或参数「不是预期类型」时发生的错误。
    
    比如，对字符串、布尔值、数值等原始类型的值使用 new 命令，就会抛出这种错误，因为 new 命令的参数应该是一个**构造函数**；调用一个对象不存在的方法的时候会抛出 TypeError 错误。

    ```javascript
    new 123
    //TypeError: 123 is not a constructor

    var obj = {}
    obj.unknownMethod()
    // TypeError: obj.unknownMethod is not a function 
    ```

5. **URIError**

    > `URIError` 是 URI 相关函数的「参数不正确」时抛出的错误。
    
    主要涉及 `encodeURI()`、`decodeURI()`、`encodeURIComponent()`、`decodeURIComponent()`、`escape()` 和 `unescape()` 这六个函数，不过后两个函数已经被废弃了。

    ```javascript
    decodeURI('%2')
    // URIError: URI malformed
    ```

6. **EvalError**

    > eval 函数没有被正确执行时，会抛出 EvalError 错误。该错误类型已经不再在 ES5 中出现了，只是为了保证与以前代码兼容，才继续保留，这里就不多介绍。

以上这 6 种派生错误，连同原始的 Error 对象，都是「构造函数」（ constructor ）。开发者可以使用它们，人为地生成错误对象的实例。

```javascript
new Error('出错了！')
new RangeError('出错了，变量超出有效范围！')
new TypeError('出错了，变量类型无效！')
```

---

### 自定义错误

除了上面介绍的 6 中原生错误加上原始错误 `Error`，用户还可以自定义错误对象。

```javascript
function UserError(message) {
   this.message = message || "默认信息"
   this.name = "UserError"
}

UserError.prototype = new Error() // 继承 Error 对象
UserError.prototype.constructor = UserError

new UserError("这是自定义的错误！")
```

---

### throw 语句

> 作用：中断程序执行，抛出一个意外或错误。它接受一个**表达式**作为参数，可以抛出**各种值**。

```javascript
// 抛出一个字符串
throw "Error！"

// 抛出一个数值
throw 42

// 抛出一个布尔值
throw true

// 抛出一个对象
throw {toString: function() { return "Error!" } }
```

JavaScript 引擎一旦遇到 **throw** 语句，就会停止执行后面的语句，并将 **throw** 语句的参数值，返回给用户。

---

### try … catch 结构

**try...catch** 结构是为了能够对错误进行处理。

```javascript
try {
  throw new Error('出错了!')
  console.log('不执行')
} catch (e) {
  console.log(e.name + ": " + e.message)
  console.log(e.stack)
}
console.log('执行')
// Error: 出错了!
// Error: 出错了!
//   at <anonymous>:3:9
// 执行
```

**try** 代码块一旦抛出错误（上例用的是 throw 语句），JavaScript 引擎就立即把代码的执行，转到 **catch** 代码块，不再执行后面的语句。可以看作，错误可以被 **catch** 代码块捕获。**catch** 接受一个参数，表示 **try** 代码块抛出的值（ throw 的参数 ）。**catch** 代码块捕获错误之后，程序不会中断，会按照正常流程继续执行下去。

可以在 **catch** 语句中添加 `if` 语句判断不同类型的错误：

```javascript
try {
  foo.bar()
} catch (e) {
  // 判断错误类型 EvalError 还是 RangeError
  if (e instanceof EvalError) {
    console.log(e.name + ": " + e.message)
  } else if (e instanceof RangeError) {
    console.log(e.name + ": " + e.message)
  }
  // ...
}
```

    try...catch 结构是 JavaScript 语言受到 Java 语言影响的一个明显的例子。这种结构多多少少是对结构化编程原则一种破坏，处理不当就会变成类似 goto 语句的效果，应该谨慎使用。

---

### finally 代码块

**try...catch** 结构允许在最后添加一个 **finally** 代码块，表示不管是否出现错误，都必需在最后运行的语句。

```javascript
function cleansUp() {
  try {
    throw new Error('出错了……')
    console.log('此行不会执行')
  } finally {
    console.log('完成清理工作')
  }
}

cleansUp()
// 完成清理工作
// Error: 出错了……
```

上面的代码尽管抛出了一个错误，但是执行了 **finally** 语句，然后程序中断在抛出错误的地方。

```javascript
function idle(x) {
  try {
    console.log(x)
    return 'result'
  } finally {
    console.log("FINALLY")
  }
}

idle('hello')
// hello
// FINALLY
// "result"
```

上面的代码表示尽管 **return** 语句在前，**finally** 代码块依然会得到执行，且在其执行完毕后，才会显示return语句的值。

```javascript
var count = 0
function countUp() {
  try {
    return count
  } finally {
    count++
    console.log('finally: count = ' + count)
  }
}

countUp()
// finally: count = 1
// 0
count
// 1
```

这个例子表示的是：**return** 语句的 `count` 的值，是在 **finally** 代码块运行之前就获取到了，但是会在 **finally** 语句结束之后才执行 **return**。

可能听起来有点绕，我刚开始看的时候也是这样，但是结合上面三个例子后我分析一波：

> 在 **try...catch** 结构中，先执行 **try** 中的语句，不管有没有出错，**finally** 语句都会在 **try** 语句执行完毕（ 没出错 ）或者 **catch** 语句执行完毕（ 出错 ）后，执行 **finally** 语句，然后最后再返回需要 **return** 的值，但是由于 **return** 语句在 **try** 中，已经获取到了需要 return 的值，只是函数的最后才返回（ 即在 finally 后 ）。

```javascript
function f() {
  try {
    console.log(0)
    throw 'bug'
  } catch(e) {
    console.log(e)
    console.log(1)
    return true // 这句原本会延迟到finally代码块结束再执行
    console.log(2) // 不会运行
  } finally {
    console.log(3)
    return false // 这句会覆盖掉前面那句return
    console.log(4) // 不会运行
  }

  console.log(5) // 不会运行
}

var result = f()
// 0
// bug
// 1
// 3

result
// false
```

上面代码中，**catch** 代码块结束执行之前，会先执行 **finally** 代码块。从 **catch** 转入 **finally** 的标志，不仅有 **return** 语句，还有 **throw** 语句。

另外，进入 **catch** 代码块之后，一遇到 **throw** 语句，就会去执行 **finally** 代码块，其中有 `return false` 语句，因此就直接返回了，不再会回去执行 **catch** 代码块剩下的部分了。